<?xml version="1.0" ?>
<robot name="cansat" xmlns:xacro="http://www.ros.org/wiki/xacro">

<xacro:include filename="$(find cansat_description)/urdf/materials.xacro" />
<xacro:include filename="$(find cansat_description)/urdf/cansat.trans" />
<xacro:include filename="$(find cansat_description)/urdf/cansat.gazebo" />
<link name="base_link">
  <inertial>
    <origin xyz="0.0 0.0 0.05000000000000001" rpy="0 0 0"/>
    <mass value="0.9419999999999997"/>
    <inertia ixx="0.00052" iyy="0.000803" izz="0.001287" ixy="0.0" iyz="-0.0" ixz="0.0"/>
  </inertial>
  <visual>
    <origin xyz="0 0 0" rpy="0 0 0"/>
    <geometry>
      <mesh filename="file://$(find cansat_description)/meshes/base_link.stl" scale="0.001 0.001 0.001"/>
    </geometry>
    <material name="silver"/>
  </visual>
  <collision>
    <origin xyz="0 0 0" rpy="0 0 0"/>
    <geometry>
      <mesh filename="file://$(find cansat_description)/meshes/base_link.stl" scale="0.001 0.001 0.001"/>
    </geometry>
  </collision>
</link>

<link name="wheel_right_1">
  <inertial>
    <origin xyz="0.0049999999999999975 -7.237528875152536e-18 -1.3877787807814457e-17" rpy="0 0 0"/>
    <mass value="0.6165375582669969"/>
    <inertia ixx="0.000771" iyy="0.00039" izz="0.00039" ixy="-0.0" iyz="-0.0" ixz="-0.0"/>
  </inertial>
  <visual>
    <origin xyz="-0.05 -0.0 -0.05" rpy="0 0 0"/>
    <geometry>
      <mesh filename="file://$(find cansat_description)/meshes/wheel_right_1.stl" scale="0.001 0.001 0.001"/>
    </geometry>
    <material name="silver"/>
  </visual>
  <collision>
    <origin xyz="-0.05 -0.0 -0.05" rpy="0 0 0"/>
    <geometry>
      <mesh filename="file://$(find cansat_description)/meshes/wheel_right_1.stl" scale="0.001 0.001 0.001"/>
    </geometry>
  </collision>
</link>

<link name="wheel_left_1">
  <inertial>
    <origin xyz="-0.0049999999999999975 -7.237528875152536e-18 -1.3877787807814457e-17" rpy="0 0 0"/>
    <mass value="0.6165375582669969"/>
    <inertia ixx="0.000771" iyy="0.00039" izz="0.00039" ixy="0.0" iyz="-0.0" ixz="0.0"/>
  </inertial>
  <visual>
    <origin xyz="0.05 -0.0 -0.05" rpy="0 0 0"/>
    <geometry>
      <mesh filename="file://$(find cansat_description)/meshes/wheel_left_1.stl" scale="0.001 0.001 0.001"/>
    </geometry>
    <material name="silver"/>
  </visual>
  <collision>
    <origin xyz="0.05 -0.0 -0.05" rpy="0 0 0"/>
    <geometry>
      <mesh filename="file://$(find cansat_description)/meshes/wheel_left_1.stl" scale="0.001 0.001 0.001"/>
    </geometry>
  </collision>
</link>

<joint name="‰ñ“] 1" type="continuous">
  <origin xyz="0.05 0.0 0.05" rpy="0 0 0"/>
  <parent link="base_link"/>
  <child link="wheel_right_1"/>
  <axis xyz="1.0 0.0 0.0"/>
</joint>

<joint name="‰ñ“] 2" type="continuous">
  <origin xyz="-0.05 0.0 0.05" rpy="0 0 0"/>
  <parent link="base_link"/>
  <child link="wheel_left_1"/>
  <axis xyz="-1.0 0.0 0.0"/>
</joint>

</robot>
